# TRANSLATION OF THE BASE LIBRARY
#
msgid ""
msgstr ""
"Project-Id-Version: 0.0.1\n"
"POT-Creation-Date: 2020-01-01 00:00-0300\n"
"PO-Revision-Date: 2024-05-18 01:20-0300\n"
"Last-Translator: \n"
"Language-Team: \n"
"Language: en\n"
"MIME-Version: 1.0\n"
"Content-Type: text/plain; charset=UTF-8\n"
"Content-Transfer-Encoding: 8bit\n"
"Plural-Forms: nplurals=2; plural=(n != 1);\n"

#: web_flask.py:1
msgid "Los-datos-recibidos-no-se-procesaron"
msgstr "The data received was not processed correctly"

#: web_flask.py:2
msgid "Error-no-manejado"
msgstr "Internal Server Error"

#: web_flask.py:3
msgid "API-key-invalida"
msgstr "Invalid API key"

#: web_flask.py:4
msgid "Encabezado-de-autorizacion-invalido"
msgstr "Invalid authorization header"

#: web_flask.py:5
msgid "Token-invalido"
msgstr "Invalid or expired token"

#: servicio.py:1
msgid "No-autorizado-para-acceder"
msgstr "You do not have permissions to perform this action"

#: web_fastapi.py:1
msgid "Los-datos-recibidos-son-invalidos"
msgstr "The data received is not valid"

#: exportador_word.py:1
msgid "Error-en-exportador-Word"
msgstr "Error in Word exporter"

#: exportador_pdf.py:1
msgid "Error-en-exportador-PDF"
msgstr "Error in PDF exporter"

#: exportador_excel.py:1
msgid "Error-en-exportador-Excel"
msgstr "Error in Excel exporter"

#: exportador_csv.py:1
msgid "Error-en-exportador-CSV"
msgstr "Error in CSV exporter"

#: web.py:1
msgid "El-archivo-ya-existe"
msgstr "A file named {name} already exists"

#: web.py:2
msgid "Error-al-guardar-el-archivo"
msgstr "Error saving file"

#: adaptadores.py:1
msgid "Archivo-cargado-con-exito"
msgstr "The file was uploaded successfully"

#: web_fastapi.py:2
msgid "Tipo-de-carga-no-valido"
msgstr "Invalid upload type"

#: web_flask.py:6
msgid "No-se-recibio-ninguna-carga"
msgstr "No upload received"

#: dominio.py:1
msgid "La-carga-recibida-no-contiene-archivo"
msgstr "The received upload does not contain a file"

#: dominio.py:2
msgid "El-tipo-de-archivo-no-esta-permitido"
msgstr "File type is not allowed"

#: dominio.py:3
msgid "El-archivo-supera-el-peso-maximo-aceptado"
msgstr "The file exceeds the maximum accepted size"

#: disco_local.py:1
msgid "Archivo-no-encontrado"
msgstr "The file was not found"

#: disco_local.py:2
msgid "Permiso-denegado-para-eliminar-el-archivo"
msgstr "Permission denied to delete file"

#: disco_local.py:3
msgid "Error-desconocido-al-acceder-al-archivo"
msgstr "Unknown error accessing file"

#: disco_local.py:4
msgid "Permiso-denegado-para-escribir-el-archivo"
msgstr "Permission denied to write the file"

#: disco_local.py:5
msgid "Permiso-denegado-para-abrir-el-archivo"
msgstr "Permission denied to open file"

#: disco_local.py:6
msgid "Error-de-IO-al-escribir-el-archivo"
msgstr "I/O error writing to file"

#: disco_local.py:7
msgid "La-carpeta-no-existe"
msgstr "The folder does not exist"

#: disco_local.py:8
msgid "Permiso-denegado-para-eliminar-la-carpeta"
msgstr "Permission denied to delete folder"

#: disco_local.py:9
msgid "Error-del-sistema-operativo-al-eliminar-la-carpeta"
msgstr "OS error when deleting folder"

#: disco_local.py:10
msgid "Permiso-denegado-para-crear-la-carpeta"
msgstr "Permission denied to create folder"

#: disco_local.py:11
msgid "Error-del-sistema-operativo-al-crear-la-carpeta"
msgstr "Operating system error creating folder"

#: disco_local.py:12
msgid "Error-desconocido-al-acceder-a-la-carpeta"
msgstr "Unknown error accessing folder"

